Unloading StdEnv/2020

The following have been reloaded with a version change:
  1) gcccore/.9.3.0 => gcccore/.7.3.0       3) mii/1.1.2 => mii/1.1.1
  2) imkl/2020.1.217 => imkl/2018.3.222


Lmod is automatically replacing "gcc/7.3.0" with "intel/2016.4".


Inactive Modules:
  1) ampl-mp/3.1.0     2) ipopt/3.12.13

The following have been reloaded with a version change:
  1) gcccore/.7.3.0 => gcccore/.5.4.0     2) imkl/2018.3.222 => imkl/11.3.4.258

Looking in links: /cvmfs/soft.computecanada.ca/custom/python/wheelhouse/nix/avx512, /cvmfs/soft.computecanada.ca/custom/python/wheelhouse/nix/avx2, /cvmfs/soft.computecanada.ca/custom/python/wheelhouse/nix/generic, /cvmfs/soft.computecanada.ca/custom/python/wheelhouse/generic
WARNING: Retrying (Retry(total=4, connect=None, read=None, redirect=None, status=None)) after connection broken by 'NewConnectionError('<pip._vendor.urllib3.connection.HTTPSConnection object at 0x2b9e57b6e210>: Failed to establish a new connection: [Errno 101] Network is unreachable')': /simple/sklearn/
WARNING: Retrying (Retry(total=3, connect=None, read=None, redirect=None, status=None)) after connection broken by 'NewConnectionError('<pip._vendor.urllib3.connection.HTTPSConnection object at 0x2b9e5d420050>: Failed to establish a new connection: [Errno 101] Network is unreachable')': /simple/sklearn/
WARNING: Retrying (Retry(total=2, connect=None, read=None, redirect=None, status=None)) after connection broken by 'NewConnectionError('<pip._vendor.urllib3.connection.HTTPSConnection object at 0x2b9e5d420090>: Failed to establish a new connection: [Errno 101] Network is unreachable')': /simple/sklearn/
WARNING: Retrying (Retry(total=1, connect=None, read=None, redirect=None, status=None)) after connection broken by 'NewConnectionError('<pip._vendor.urllib3.connection.HTTPSConnection object at 0x2b9e5d4204d0>: Failed to establish a new connection: [Errno 101] Network is unreachable')': /simple/sklearn/
WARNING: Retrying (Retry(total=0, connect=None, read=None, redirect=None, status=None)) after connection broken by 'NewConnectionError('<pip._vendor.urllib3.connection.HTTPSConnection object at 0x2b9e5d420850>: Failed to establish a new connection: [Errno 101] Network is unreachable')': /simple/sklearn/
Processing /cvmfs/soft.computecanada.ca/custom/python/wheelhouse/generic/sklearn-0.0+computecanada-py2.py3-none-any.whl
WARNING: Retrying (Retry(total=4, connect=None, read=None, redirect=None, status=None)) after connection broken by 'NewConnectionError('<pip._vendor.urllib3.connection.HTTPSConnection object at 0x2b9e5ef503d0>: Failed to establish a new connection: [Errno 101] Network is unreachable')': /simple/scikit-learn/
WARNING: Retrying (Retry(total=3, connect=None, read=None, redirect=None, status=None)) after connection broken by 'NewConnectionError('<pip._vendor.urllib3.connection.HTTPSConnection object at 0x2b9e5ef50810>: Failed to establish a new connection: [Errno 101] Network is unreachable')': /simple/scikit-learn/
WARNING: Retrying (Retry(total=2, connect=None, read=None, redirect=None, status=None)) after connection broken by 'NewConnectionError('<pip._vendor.urllib3.connection.HTTPSConnection object at 0x2b9e5ef50b50>: Failed to establish a new connection: [Errno 101] Network is unreachable')': /simple/scikit-learn/
WARNING: Retrying (Retry(total=1, connect=None, read=None, redirect=None, status=None)) after connection broken by 'NewConnectionError('<pip._vendor.urllib3.connection.HTTPSConnection object at 0x2b9e5efd6050>: Failed to establish a new connection: [Errno 101] Network is unreachable')': /simple/scikit-learn/
WARNING: Retrying (Retry(total=0, connect=None, read=None, redirect=None, status=None)) after connection broken by 'NewConnectionError('<pip._vendor.urllib3.connection.HTTPSConnection object at 0x2b9e5efd6250>: Failed to establish a new connection: [Errno 101] Network is unreachable')': /simple/scikit-learn/
Processing /cvmfs/soft.computecanada.ca/custom/python/wheelhouse/generic/scikit_learn-0.23.0+computecanada-cp37-cp37m-linux_x86_64.whl
Requirement already satisfied: scipy>=0.19.1 in /cvmfs/soft.computecanada.ca/easybuild/software/2017/Core/scipy-stack/2019a/lib/python3.7/site-packages (from scikit-learn->sklearn) (1.2.0)
WARNING: Retrying (Retry(total=4, connect=None, read=None, redirect=None, status=None)) after connection broken by 'NewConnectionError('<pip._vendor.urllib3.connection.HTTPSConnection object at 0x2b9e5ef47850>: Failed to establish a new connection: [Errno 101] Network is unreachable')': /simple/joblib/
WARNING: Retrying (Retry(total=3, connect=None, read=None, redirect=None, status=None)) after connection broken by 'NewConnectionError('<pip._vendor.urllib3.connection.HTTPSConnection object at 0x2b9e5f706850>: Failed to establish a new connection: [Errno 101] Network is unreachable')': /simple/joblib/
WARNING: Retrying (Retry(total=2, connect=None, read=None, redirect=None, status=None)) after connection broken by 'NewConnectionError('<pip._vendor.urllib3.connection.HTTPSConnection object at 0x2b9e5f758310>: Failed to establish a new connection: [Errno 101] Network is unreachable')': /simple/joblib/
WARNING: Retrying (Retry(total=1, connect=None, read=None, redirect=None, status=None)) after connection broken by 'NewConnectionError('<pip._vendor.urllib3.connection.HTTPSConnection object at 0x2b9e5f758d50>: Failed to establish a new connection: [Errno 101] Network is unreachable')': /simple/joblib/
WARNING: Retrying (Retry(total=0, connect=None, read=None, redirect=None, status=None)) after connection broken by 'NewConnectionError('<pip._vendor.urllib3.connection.HTTPSConnection object at 0x2b9e5f75f390>: Failed to establish a new connection: [Errno 101] Network is unreachable')': /simple/joblib/
Processing /cvmfs/soft.computecanada.ca/custom/python/wheelhouse/generic/joblib-1.2.0+computecanada-py3-none-any.whl
WARNING: Retrying (Retry(total=4, connect=None, read=None, redirect=None, status=None)) after connection broken by 'NewConnectionError('<pip._vendor.urllib3.connection.HTTPSConnection object at 0x2b9e5febf910>: Failed to establish a new connection: [Errno 101] Network is unreachable')': /simple/threadpoolctl/
WARNING: Retrying (Retry(total=3, connect=None, read=None, redirect=None, status=None)) after connection broken by 'NewConnectionError('<pip._vendor.urllib3.connection.HTTPSConnection object at 0x2b9e5febfd50>: Failed to establish a new connection: [Errno 101] Network is unreachable')': /simple/threadpoolctl/
WARNING: Retrying (Retry(total=2, connect=None, read=None, redirect=None, status=None)) after connection broken by 'NewConnectionError('<pip._vendor.urllib3.connection.HTTPSConnection object at 0x2b9e5fec70d0>: Failed to establish a new connection: [Errno 101] Network is unreachable')': /simple/threadpoolctl/
WARNING: Retrying (Retry(total=1, connect=None, read=None, redirect=None, status=None)) after connection broken by 'NewConnectionError('<pip._vendor.urllib3.connection.HTTPSConnection object at 0x2b9e5fec73d0>: Failed to establish a new connection: [Errno 101] Network is unreachable')': /simple/threadpoolctl/
WARNING: Retrying (Retry(total=0, connect=None, read=None, redirect=None, status=None)) after connection broken by 'NewConnectionError('<pip._vendor.urllib3.connection.HTTPSConnection object at 0x2b9e5fec7750>: Failed to establish a new connection: [Errno 101] Network is unreachable')': /simple/threadpoolctl/
Processing /cvmfs/soft.computecanada.ca/custom/python/wheelhouse/generic/threadpoolctl-3.1.0+computecanada-py3-none-any.whl
Requirement already satisfied: numpy>=1.13.3 in /lustre03/project/6043437/mheuill/MYENV/lib/python3.7/site-packages (from scikit-learn->sklearn) (1.20.2+computecanada)
Installing collected packages: threadpoolctl, joblib, scikit-learn, sklearn
ERROR: Could not install packages due to an OSError: [Errno 122] Disk quota exceeded

/lustre03/project/6043437/mheuill/MYENV/lib/python3.7/site-packages/setuptools/_importlib.py:23: UserWarning: `importlib-metadata` version is incompatible with `setuptools`.
This problem is likely to be solved by installing an updated version of `importlib-metadata`.
  warnings.warn(msg)  # Ensure a descriptive message is shown.
Traceback (most recent call last):
  File "./partial_monitoring/evaluation.py", line 27, in <module>
    from sklearn.preprocessing import PolynomialFeatures
ModuleNotFoundError: No module named 'sklearn'
